2022-06-18 18:37:20 WARNING (SyncWorker_1) [homeassistant.loader] We found a custom integration browser_mod which has not been tested by Home Assistant. This component might cause stability problems, be sure to disable it if you experience issues with Home Assistant
2022-06-18 18:37:20 WARNING (SyncWorker_0) [homeassistant.loader] We found a custom integration tapo_control which has not been tested by Home Assistant. This component might cause stability problems, be sure to disable it if you experience issues with Home Assistant
2022-06-18 18:37:20 WARNING (SyncWorker_2) [homeassistant.loader] We found a custom integration hacs which has not been tested by Home Assistant. This component might cause stability problems, be sure to disable it if you experience issues with Home Assistant
2022-06-18 18:37:25 WARNING (MainThread) [hass_nabucasa.cloud_api] Fetched https://alexa-api.nabucasa.com/access_token (400)
2022-06-18 18:37:26 ERROR (MainThread) [homeassistant.components.deconz] Error connecting to deCONZ gateway at 10.0.0.32
2022-06-18 18:37:26 WARNING (MainThread) [homeassistant.config_entries] Config entry '00212E07826C' for deconz integration not ready yet; Retrying in background
2022-06-18 18:37:34 ERROR (MainThread) [homeassistant.components.deconz] Error connecting to deCONZ gateway at 10.0.0.32
2022-06-18 18:37:48 ERROR (MainThread) [homeassistant.components.deconz] Error connecting to deCONZ gateway at 10.0.0.32
2022-06-18 18:38:11 ERROR (MainThread) [homeassistant.components.deconz] Error connecting to deCONZ gateway at 10.0.0.32
2022-06-18 18:38:54 ERROR (MainThread) [homeassistant.components.deconz] Error connecting to deCONZ gateway at 10.0.0.32
2022-06-18 18:40:18 ERROR (MainThread) [homeassistant.components.deconz] Error connecting to deCONZ gateway at 10.0.0.32
2022-06-18 18:41:41 ERROR (MainThread) [homeassistant.components.deconz] Error connecting to deCONZ gateway at 10.0.0.32
2022-06-18 18:43:05 ERROR (MainThread) [homeassistant.components.deconz] Error connecting to deCONZ gateway at 10.0.0.32
2022-06-18 18:44:28 ERROR (MainThread) [homeassistant.components.deconz] Error connecting to deCONZ gateway at 10.0.0.32
2022-06-18 18:45:51 ERROR (MainThread) [homeassistant.components.deconz] Error connecting to deCONZ gateway at 10.0.0.32
2022-06-18 18:47:15 ERROR (MainThread) [homeassistant.components.deconz] Error connecting to deCONZ gateway at 10.0.0.32
2022-06-18 18:48:38 ERROR (MainThread) [homeassistant.components.deconz] Error connecting to deCONZ gateway at 10.0.0.32
2022-06-18 18:50:02 ERROR (MainThread) [homeassistant.components.deconz] Error connecting to deCONZ gateway at 10.0.0.32
2022-06-18 18:51:25 ERROR (MainThread) [homeassistant.components.deconz] Error connecting to deCONZ gateway at 10.0.0.32
2022-06-18 18:52:47 ERROR (MainThread) [homeassistant.components.deconz] Error connecting to deCONZ gateway at 10.0.0.32
2022-06-18 18:54:12 ERROR (MainThread) [homeassistant.components.deconz] Error connecting to deCONZ gateway at 10.0.0.32
2022-06-18 18:55:35 ERROR (MainThread) [homeassistant.components.deconz] Error connecting to deCONZ gateway at 10.0.0.32
2022-06-18 18:56:58 ERROR (MainThread) [homeassistant.components.deconz] Error connecting to deCONZ gateway at 10.0.0.32
2022-06-18 18:58:22 ERROR (MainThread) [homeassistant.components.deconz] Error connecting to deCONZ gateway at 10.0.0.32
2022-06-18 18:59:46 ERROR (MainThread) [homeassistant.components.deconz] Error connecting to deCONZ gateway at 10.0.0.32
2022-06-18 19:01:09 ERROR (MainThread) [homeassistant.components.deconz] Error connecting to deCONZ gateway at 10.0.0.32
2022-06-18 19:02:33 ERROR (MainThread) [homeassistant.components.deconz] Error connecting to deCONZ gateway at 10.0.0.32
2022-06-18 19:03:56 ERROR (MainThread) [homeassistant.components.deconz] Error connecting to deCONZ gateway at 10.0.0.32
2022-06-18 19:05:19 ERROR (MainThread) [homeassistant.components.deconz] Error connecting to deCONZ gateway at 10.0.0.32
2022-06-18 19:06:43 ERROR (MainThread) [homeassistant.components.deconz] Error connecting to deCONZ gateway at 10.0.0.32
2022-06-18 19:08:06 ERROR (MainThread) [homeassistant.components.deconz] Error connecting to deCONZ gateway at 10.0.0.32
2022-06-18 19:09:26 ERROR (MainThread) [homeassistant.components.deconz] Error connecting to deCONZ gateway at 10.0.0.32
2022-06-18 19:10:47 ERROR (MainThread) [homeassistant.components.deconz] Error connecting to deCONZ gateway at 10.0.0.32
2022-06-18 19:12:07 ERROR (MainThread) [homeassistant.components.deconz] Error connecting to deCONZ gateway at 10.0.0.32
2022-06-18 19:13:27 ERROR (MainThread) [homeassistant.components.deconz] Error connecting to deCONZ gateway at 10.0.0.32
2022-06-18 19:14:48 ERROR (MainThread) [homeassistant.components.deconz] Error connecting to deCONZ gateway at 10.0.0.32
2022-06-18 19:16:09 ERROR (MainThread) [homeassistant.components.deconz] Error connecting to deCONZ gateway at 10.0.0.32
2022-06-18 19:17:29 ERROR (MainThread) [homeassistant.components.deconz] Error connecting to deCONZ gateway at 10.0.0.32
2022-06-18 19:18:49 ERROR (MainThread) [homeassistant.components.deconz] Error connecting to deCONZ gateway at 10.0.0.32
2022-06-18 19:20:10 ERROR (MainThread) [homeassistant.components.deconz] Error connecting to deCONZ gateway at 10.0.0.32
2022-06-18 19:21:30 ERROR (MainThread) [homeassistant.components.deconz] Error connecting to deCONZ gateway at 10.0.0.32
2022-06-18 19:22:50 ERROR (MainThread) [homeassistant.components.deconz] Error connecting to deCONZ gateway at 10.0.0.32
2022-06-18 19:24:10 ERROR (MainThread) [homeassistant.components.deconz] Error connecting to deCONZ gateway at 10.0.0.32
2022-06-18 19:25:31 ERROR (MainThread) [homeassistant.components.deconz] Error connecting to deCONZ gateway at 10.0.0.32
2022-06-18 19:26:52 ERROR (MainThread) [homeassistant.components.deconz] Error connecting to deCONZ gateway at 10.0.0.32
2022-06-18 19:27:12 WARNING (MainThread) [hass_nabucasa.cloud_api] Fetched https://alexa-api.nabucasa.com/access_token (400)
2022-06-18 19:27:12 ERROR (MainThread) [homeassistant] Error doing job: Task exception was never retrieved
Traceback (most recent call last):
  File "/usr/src/homeassistant/homeassistant/components/cloud/alexa_config.py", line 367, in _handle_entity_registry_updated
    await self._sync_helper(to_update, to_remove)
  File "/usr/src/homeassistant/homeassistant/components/cloud/alexa_config.py", line 311, in _sync_helper
    await self.async_get_access_token()
  File "/usr/src/homeassistant/homeassistant/components/cloud/alexa_config.py", line 173, in async_get_access_token
    raise alexa_errors.RequireRelink
homeassistant.components.alexa.errors.RequireRelink
2022-06-18 19:27:12 WARNING (MainThread) [hass_nabucasa.cloud_api] Fetched https://alexa-api.nabucasa.com/access_token (400)
2022-06-18 19:27:12 ERROR (MainThread) [homeassistant] Error doing job: Task exception was never retrieved
Traceback (most recent call last):
  File "/usr/src/homeassistant/homeassistant/components/cloud/alexa_config.py", line 367, in _handle_entity_registry_updated
    await self._sync_helper(to_update, to_remove)
  File "/usr/src/homeassistant/homeassistant/components/cloud/alexa_config.py", line 311, in _sync_helper
    await self.async_get_access_token()
  File "/usr/src/homeassistant/homeassistant/components/cloud/alexa_config.py", line 173, in async_get_access_token
    raise alexa_errors.RequireRelink
homeassistant.components.alexa.errors.RequireRelink
2022-06-18 19:27:12 WARNING (MainThread) [hass_nabucasa.cloud_api] Fetched https://alexa-api.nabucasa.com/access_token (400)
2022-06-18 19:27:12 ERROR (MainThread) [homeassistant] Error doing job: Task exception was never retrieved
Traceback (most recent call last):
  File "/usr/src/homeassistant/homeassistant/components/cloud/alexa_config.py", line 367, in _handle_entity_registry_updated
    await self._sync_helper(to_update, to_remove)
  File "/usr/src/homeassistant/homeassistant/components/cloud/alexa_config.py", line 311, in _sync_helper
    await self.async_get_access_token()
  File "/usr/src/homeassistant/homeassistant/components/cloud/alexa_config.py", line 173, in async_get_access_token
    raise alexa_errors.RequireRelink
homeassistant.components.alexa.errors.RequireRelink
2022-06-18 19:27:12 WARNING (MainThread) [hass_nabucasa.cloud_api] Fetched https://alexa-api.nabucasa.com/access_token (400)
2022-06-18 19:27:12 ERROR (MainThread) [homeassistant] Error doing job: Task exception was never retrieved
Traceback (most recent call last):
  File "/usr/src/homeassistant/homeassistant/components/cloud/alexa_config.py", line 367, in _handle_entity_registry_updated
    await self._sync_helper(to_update, to_remove)
  File "/usr/src/homeassistant/homeassistant/components/cloud/alexa_config.py", line 311, in _sync_helper
    await self.async_get_access_token()
  File "/usr/src/homeassistant/homeassistant/components/cloud/alexa_config.py", line 173, in async_get_access_token
    raise alexa_errors.RequireRelink
homeassistant.components.alexa.errors.RequireRelink
2022-06-18 19:27:12 WARNING (MainThread) [hass_nabucasa.cloud_api] Fetched https://alexa-api.nabucasa.com/access_token (400)
2022-06-18 19:27:12 ERROR (MainThread) [homeassistant] Error doing job: Task exception was never retrieved
Traceback (most recent call last):
  File "/usr/src/homeassistant/homeassistant/components/cloud/alexa_config.py", line 367, in _handle_entity_registry_updated
    await self._sync_helper(to_update, to_remove)
  File "/usr/src/homeassistant/homeassistant/components/cloud/alexa_config.py", line 311, in _sync_helper
    await self.async_get_access_token()
  File "/usr/src/homeassistant/homeassistant/components/cloud/alexa_config.py", line 173, in async_get_access_token
    raise alexa_errors.RequireRelink
homeassistant.components.alexa.errors.RequireRelink
2022-06-18 19:27:12 WARNING (MainThread) [hass_nabucasa.cloud_api] Fetched https://alexa-api.nabucasa.com/access_token (400)
2022-06-18 19:27:12 ERROR (MainThread) [homeassistant] Error doing job: Task exception was never retrieved
Traceback (most recent call last):
  File "/usr/src/homeassistant/homeassistant/components/cloud/alexa_config.py", line 367, in _handle_entity_registry_updated
    await self._sync_helper(to_update, to_remove)
  File "/usr/src/homeassistant/homeassistant/components/cloud/alexa_config.py", line 311, in _sync_helper
    await self.async_get_access_token()
  File "/usr/src/homeassistant/homeassistant/components/cloud/alexa_config.py", line 173, in async_get_access_token
    raise alexa_errors.RequireRelink
homeassistant.components.alexa.errors.RequireRelink
2022-06-18 19:27:12 WARNING (MainThread) [hass_nabucasa.cloud_api] Fetched https://alexa-api.nabucasa.com/access_token (400)
2022-06-18 19:27:12 ERROR (MainThread) [homeassistant] Error doing job: Task exception was never retrieved
Traceback (most recent call last):
  File "/usr/src/homeassistant/homeassistant/components/cloud/alexa_config.py", line 367, in _handle_entity_registry_updated
    await self._sync_helper(to_update, to_remove)
  File "/usr/src/homeassistant/homeassistant/components/cloud/alexa_config.py", line 311, in _sync_helper
    await self.async_get_access_token()
  File "/usr/src/homeassistant/homeassistant/components/cloud/alexa_config.py", line 173, in async_get_access_token
    raise alexa_errors.RequireRelink
homeassistant.components.alexa.errors.RequireRelink
2022-06-18 19:27:12 WARNING (MainThread) [hass_nabucasa.cloud_api] Fetched https://alexa-api.nabucasa.com/access_token (400)
2022-06-18 19:27:12 ERROR (MainThread) [homeassistant] Error doing job: Task exception was never retrieved
Traceback (most recent call last):
  File "/usr/src/homeassistant/homeassistant/components/cloud/alexa_config.py", line 367, in _handle_entity_registry_updated
    await self._sync_helper(to_update, to_remove)
  File "/usr/src/homeassistant/homeassistant/components/cloud/alexa_config.py", line 311, in _sync_helper
    await self.async_get_access_token()
  File "/usr/src/homeassistant/homeassistant/components/cloud/alexa_config.py", line 173, in async_get_access_token
    raise alexa_errors.RequireRelink
homeassistant.components.alexa.errors.RequireRelink
2022-06-18 19:27:12 WARNING (MainThread) [hass_nabucasa.cloud_api] Fetched https://alexa-api.nabucasa.com/access_token (400)
2022-06-18 19:27:12 ERROR (MainThread) [homeassistant] Error doing job: Task exception was never retrieved
Traceback (most recent call last):
  File "/usr/src/homeassistant/homeassistant/components/cloud/alexa_config.py", line 367, in _handle_entity_registry_updated
    await self._sync_helper(to_update, to_remove)
  File "/usr/src/homeassistant/homeassistant/components/cloud/alexa_config.py", line 311, in _sync_helper
    await self.async_get_access_token()
  File "/usr/src/homeassistant/homeassistant/components/cloud/alexa_config.py", line 173, in async_get_access_token
    raise alexa_errors.RequireRelink
homeassistant.components.alexa.errors.RequireRelink
2022-06-18 19:27:12 WARNING (MainThread) [hass_nabucasa.cloud_api] Fetched https://alexa-api.nabucasa.com/access_token (400)
2022-06-18 19:27:12 ERROR (MainThread) [homeassistant] Error doing job: Task exception was never retrieved
Traceback (most recent call last):
  File "/usr/src/homeassistant/homeassistant/components/cloud/alexa_config.py", line 367, in _handle_entity_registry_updated
    await self._sync_helper(to_update, to_remove)
  File "/usr/src/homeassistant/homeassistant/components/cloud/alexa_config.py", line 311, in _sync_helper
    await self.async_get_access_token()
  File "/usr/src/homeassistant/homeassistant/components/cloud/alexa_config.py", line 173, in async_get_access_token
    raise alexa_errors.RequireRelink
homeassistant.components.alexa.errors.RequireRelink
2022-06-18 19:27:12 WARNING (MainThread) [hass_nabucasa.cloud_api] Fetched https://alexa-api.nabucasa.com/access_token (400)
2022-06-18 19:27:12 ERROR (MainThread) [homeassistant] Error doing job: Task exception was never retrieved
Traceback (most recent call last):
  File "/usr/src/homeassistant/homeassistant/components/cloud/alexa_config.py", line 367, in _handle_entity_registry_updated
    await self._sync_helper(to_update, to_remove)
  File "/usr/src/homeassistant/homeassistant/components/cloud/alexa_config.py", line 311, in _sync_helper
    await self.async_get_access_token()
  File "/usr/src/homeassistant/homeassistant/components/cloud/alexa_config.py", line 173, in async_get_access_token
    raise alexa_errors.RequireRelink
homeassistant.components.alexa.errors.RequireRelink
2022-06-18 19:27:12 WARNING (MainThread) [hass_nabucasa.cloud_api] Fetched https://alexa-api.nabucasa.com/access_token (400)
2022-06-18 19:27:12 ERROR (MainThread) [homeassistant] Error doing job: Task exception was never retrieved
Traceback (most recent call last):
  File "/usr/src/homeassistant/homeassistant/components/cloud/alexa_config.py", line 367, in _handle_entity_registry_updated
    await self._sync_helper(to_update, to_remove)
  File "/usr/src/homeassistant/homeassistant/components/cloud/alexa_config.py", line 311, in _sync_helper
    await self.async_get_access_token()
  File "/usr/src/homeassistant/homeassistant/components/cloud/alexa_config.py", line 173, in async_get_access_token
    raise alexa_errors.RequireRelink
homeassistant.components.alexa.errors.RequireRelink
2022-06-18 19:27:12 WARNING (MainThread) [hass_nabucasa.cloud_api] Fetched https://alexa-api.nabucasa.com/access_token (400)
2022-06-18 19:27:12 ERROR (MainThread) [homeassistant] Error doing job: Task exception was never retrieved
Traceback (most recent call last):
  File "/usr/src/homeassistant/homeassistant/components/cloud/alexa_config.py", line 367, in _handle_entity_registry_updated
    await self._sync_helper(to_update, to_remove)
  File "/usr/src/homeassistant/homeassistant/components/cloud/alexa_config.py", line 311, in _sync_helper
    await self.async_get_access_token()
  File "/usr/src/homeassistant/homeassistant/components/cloud/alexa_config.py", line 173, in async_get_access_token
    raise alexa_errors.RequireRelink
homeassistant.components.alexa.errors.RequireRelink
2022-06-18 19:27:12 WARNING (MainThread) [hass_nabucasa.cloud_api] Fetched https://alexa-api.nabucasa.com/access_token (400)
2022-06-18 19:27:12 ERROR (MainThread) [homeassistant] Error doing job: Task exception was never retrieved
Traceback (most recent call last):
  File "/usr/src/homeassistant/homeassistant/components/cloud/alexa_config.py", line 367, in _handle_entity_registry_updated
    await self._sync_helper(to_update, to_remove)
  File "/usr/src/homeassistant/homeassistant/components/cloud/alexa_config.py", line 311, in _sync_helper
    await self.async_get_access_token()
  File "/usr/src/homeassistant/homeassistant/components/cloud/alexa_config.py", line 173, in async_get_access_token
    raise alexa_errors.RequireRelink
homeassistant.components.alexa.errors.RequireRelink
2022-06-18 19:27:12 WARNING (MainThread) [hass_nabucasa.cloud_api] Fetched https://alexa-api.nabucasa.com/access_token (400)
2022-06-18 19:27:12 ERROR (MainThread) [homeassistant] Error doing job: Task exception was never retrieved
Traceback (most recent call last):
  File "/usr/src/homeassistant/homeassistant/components/cloud/alexa_config.py", line 367, in _handle_entity_registry_updated
    await self._sync_helper(to_update, to_remove)
  File "/usr/src/homeassistant/homeassistant/components/cloud/alexa_config.py", line 311, in _sync_helper
    await self.async_get_access_token()
  File "/usr/src/homeassistant/homeassistant/components/cloud/alexa_config.py", line 173, in async_get_access_token
    raise alexa_errors.RequireRelink
homeassistant.components.alexa.errors.RequireRelink
2022-06-18 19:27:12 WARNING (MainThread) [hass_nabucasa.cloud_api] Fetched https://alexa-api.nabucasa.com/access_token (400)
2022-06-18 19:27:12 ERROR (MainThread) [homeassistant] Error doing job: Task exception was never retrieved
Traceback (most recent call last):
  File "/usr/src/homeassistant/homeassistant/components/cloud/alexa_config.py", line 367, in _handle_entity_registry_updated
    await self._sync_helper(to_update, to_remove)
  File "/usr/src/homeassistant/homeassistant/components/cloud/alexa_config.py", line 311, in _sync_helper
    await self.async_get_access_token()
  File "/usr/src/homeassistant/homeassistant/components/cloud/alexa_config.py", line 173, in async_get_access_token
    raise alexa_errors.RequireRelink
homeassistant.components.alexa.errors.RequireRelink
2022-06-18 19:27:12 WARNING (MainThread) [hass_nabucasa.cloud_api] Fetched https://alexa-api.nabucasa.com/access_token (400)
2022-06-18 19:27:12 ERROR (MainThread) [homeassistant] Error doing job: Task exception was never retrieved
Traceback (most recent call last):
  File "/usr/src/homeassistant/homeassistant/components/cloud/alexa_config.py", line 367, in _handle_entity_registry_updated
    await self._sync_helper(to_update, to_remove)
  File "/usr/src/homeassistant/homeassistant/components/cloud/alexa_config.py", line 311, in _sync_helper
    await self.async_get_access_token()
  File "/usr/src/homeassistant/homeassistant/components/cloud/alexa_config.py", line 173, in async_get_access_token
    raise alexa_errors.RequireRelink
homeassistant.components.alexa.errors.RequireRelink
2022-06-18 19:27:12 WARNING (MainThread) [hass_nabucasa.cloud_api] Fetched https://alexa-api.nabucasa.com/access_token (400)
2022-06-18 19:27:12 ERROR (MainThread) [homeassistant] Error doing job: Task exception was never retrieved
Traceback (most recent call last):
  File "/usr/src/homeassistant/homeassistant/components/cloud/alexa_config.py", line 367, in _handle_entity_registry_updated
    await self._sync_helper(to_update, to_remove)
  File "/usr/src/homeassistant/homeassistant/components/cloud/alexa_config.py", line 311, in _sync_helper
    await self.async_get_access_token()
  File "/usr/src/homeassistant/homeassistant/components/cloud/alexa_config.py", line 173, in async_get_access_token
    raise alexa_errors.RequireRelink
homeassistant.components.alexa.errors.RequireRelink
2022-06-18 19:27:12 WARNING (MainThread) [hass_nabucasa.cloud_api] Fetched https://alexa-api.nabucasa.com/access_token (400)
2022-06-18 19:27:12 ERROR (MainThread) [homeassistant] Error doing job: Task exception was never retrieved
Traceback (most recent call last):
  File "/usr/src/homeassistant/homeassistant/components/cloud/alexa_config.py", line 367, in _handle_entity_registry_updated
    await self._sync_helper(to_update, to_remove)
  File "/usr/src/homeassistant/homeassistant/components/cloud/alexa_config.py", line 311, in _sync_helper
    await self.async_get_access_token()
  File "/usr/src/homeassistant/homeassistant/components/cloud/alexa_config.py", line 173, in async_get_access_token
    raise alexa_errors.RequireRelink
homeassistant.components.alexa.errors.RequireRelink
2022-06-18 19:27:12 WARNING (MainThread) [hass_nabucasa.cloud_api] Fetched https://alexa-api.nabucasa.com/access_token (400)
2022-06-18 19:27:12 ERROR (MainThread) [homeassistant] Error doing job: Task exception was never retrieved
Traceback (most recent call last):
  File "/usr/src/homeassistant/homeassistant/components/cloud/alexa_config.py", line 367, in _handle_entity_registry_updated
    await self._sync_helper(to_update, to_remove)
  File "/usr/src/homeassistant/homeassistant/components/cloud/alexa_config.py", line 311, in _sync_helper
    await self.async_get_access_token()
  File "/usr/src/homeassistant/homeassistant/components/cloud/alexa_config.py", line 173, in async_get_access_token
    raise alexa_errors.RequireRelink
homeassistant.components.alexa.errors.RequireRelink
2022-06-18 19:27:12 WARNING (MainThread) [hass_nabucasa.cloud_api] Fetched https://alexa-api.nabucasa.com/access_token (400)
2022-06-18 19:27:12 ERROR (MainThread) [homeassistant] Error doing job: Task exception was never retrieved
Traceback (most recent call last):
  File "/usr/src/homeassistant/homeassistant/components/cloud/alexa_config.py", line 367, in _handle_entity_registry_updated
    await self._sync_helper(to_update, to_remove)
  File "/usr/src/homeassistant/homeassistant/components/cloud/alexa_config.py", line 311, in _sync_helper
    await self.async_get_access_token()
  File "/usr/src/homeassistant/homeassistant/components/cloud/alexa_config.py", line 173, in async_get_access_token
    raise alexa_errors.RequireRelink
homeassistant.components.alexa.errors.RequireRelink
2022-06-18 19:27:12 WARNING (MainThread) [hass_nabucasa.cloud_api] Fetched https://alexa-api.nabucasa.com/access_token (400)
2022-06-18 19:27:12 ERROR (MainThread) [homeassistant] Error doing job: Task exception was never retrieved
Traceback (most recent call last):
  File "/usr/src/homeassistant/homeassistant/components/cloud/alexa_config.py", line 367, in _handle_entity_registry_updated
    await self._sync_helper(to_update, to_remove)
  File "/usr/src/homeassistant/homeassistant/components/cloud/alexa_config.py", line 311, in _sync_helper
    await self.async_get_access_token()
  File "/usr/src/homeassistant/homeassistant/components/cloud/alexa_config.py", line 173, in async_get_access_token
    raise alexa_errors.RequireRelink
homeassistant.components.alexa.errors.RequireRelink
2022-06-18 19:27:12 WARNING (MainThread) [hass_nabucasa.cloud_api] Fetched https://alexa-api.nabucasa.com/access_token (400)
2022-06-18 19:27:12 ERROR (MainThread) [homeassistant] Error doing job: Task exception was never retrieved
Traceback (most recent call last):
  File "/usr/src/homeassistant/homeassistant/components/cloud/alexa_config.py", line 367, in _handle_entity_registry_updated
    await self._sync_helper(to_update, to_remove)
  File "/usr/src/homeassistant/homeassistant/components/cloud/alexa_config.py", line 311, in _sync_helper
    await self.async_get_access_token()
  File "/usr/src/homeassistant/homeassistant/components/cloud/alexa_config.py", line 173, in async_get_access_token
    raise alexa_errors.RequireRelink
homeassistant.components.alexa.errors.RequireRelink
2022-06-18 19:27:12 WARNING (MainThread) [hass_nabucasa.cloud_api] Fetched https://alexa-api.nabucasa.com/access_token (400)
2022-06-18 19:27:12 ERROR (MainThread) [homeassistant] Error doing job: Task exception was never retrieved
Traceback (most recent call last):
  File "/usr/src/homeassistant/homeassistant/components/cloud/alexa_config.py", line 367, in _handle_entity_registry_updated
    await self._sync_helper(to_update, to_remove)
  File "/usr/src/homeassistant/homeassistant/components/cloud/alexa_config.py", line 311, in _sync_helper
    await self.async_get_access_token()
  File "/usr/src/homeassistant/homeassistant/components/cloud/alexa_config.py", line 173, in async_get_access_token
    raise alexa_errors.RequireRelink
homeassistant.components.alexa.errors.RequireRelink
2022-06-18 19:27:12 WARNING (MainThread) [hass_nabucasa.cloud_api] Fetched https://alexa-api.nabucasa.com/access_token (400)
2022-06-18 19:27:12 ERROR (MainThread) [homeassistant] Error doing job: Task exception was never retrieved
Traceback (most recent call last):
  File "/usr/src/homeassistant/homeassistant/components/cloud/alexa_config.py", line 367, in _handle_entity_registry_updated
    await self._sync_helper(to_update, to_remove)
  File "/usr/src/homeassistant/homeassistant/components/cloud/alexa_config.py", line 311, in _sync_helper
    await self.async_get_access_token()
  File "/usr/src/homeassistant/homeassistant/components/cloud/alexa_config.py", line 173, in async_get_access_token
    raise alexa_errors.RequireRelink
homeassistant.components.alexa.errors.RequireRelink
2022-06-18 19:27:12 WARNING (MainThread) [hass_nabucasa.cloud_api] Fetched https://alexa-api.nabucasa.com/access_token (400)
2022-06-18 19:27:12 ERROR (MainThread) [homeassistant] Error doing job: Task exception was never retrieved
Traceback (most recent call last):
  File "/usr/src/homeassistant/homeassistant/components/cloud/alexa_config.py", line 367, in _handle_entity_registry_updated
    await self._sync_helper(to_update, to_remove)
  File "/usr/src/homeassistant/homeassistant/components/cloud/alexa_config.py", line 311, in _sync_helper
    await self.async_get_access_token()
  File "/usr/src/homeassistant/homeassistant/components/cloud/alexa_config.py", line 173, in async_get_access_token
    raise alexa_errors.RequireRelink
homeassistant.components.alexa.errors.RequireRelink
2022-06-18 19:27:12 WARNING (MainThread) [hass_nabucasa.cloud_api] Fetched https://alexa-api.nabucasa.com/access_token (400)
2022-06-18 19:27:12 ERROR (MainThread) [homeassistant] Error doing job: Task exception was never retrieved
Traceback (most recent call last):
  File "/usr/src/homeassistant/homeassistant/components/cloud/alexa_config.py", line 367, in _handle_entity_registry_updated
    await self._sync_helper(to_update, to_remove)
  File "/usr/src/homeassistant/homeassistant/components/cloud/alexa_config.py", line 311, in _sync_helper
    await self.async_get_access_token()
  File "/usr/src/homeassistant/homeassistant/components/cloud/alexa_config.py", line 173, in async_get_access_token
    raise alexa_errors.RequireRelink
homeassistant.components.alexa.errors.RequireRelink
2022-06-18 19:27:12 WARNING (MainThread) [hass_nabucasa.cloud_api] Fetched https://alexa-api.nabucasa.com/access_token (400)
2022-06-18 19:27:12 ERROR (MainThread) [homeassistant] Error doing job: Task exception was never retrieved
Traceback (most recent call last):
  File "/usr/src/homeassistant/homeassistant/components/cloud/alexa_config.py", line 367, in _handle_entity_registry_updated
    await self._sync_helper(to_update, to_remove)
  File "/usr/src/homeassistant/homeassistant/components/cloud/alexa_config.py", line 311, in _sync_helper
    await self.async_get_access_token()
  File "/usr/src/homeassistant/homeassistant/components/cloud/alexa_config.py", line 173, in async_get_access_token
    raise alexa_errors.RequireRelink
homeassistant.components.alexa.errors.RequireRelink
2022-06-18 19:27:12 WARNING (MainThread) [hass_nabucasa.cloud_api] Fetched https://alexa-api.nabucasa.com/access_token (400)
2022-06-18 19:27:12 ERROR (MainThread) [homeassistant] Error doing job: Task exception was never retrieved
Traceback (most recent call last):
  File "/usr/src/homeassistant/homeassistant/components/cloud/alexa_config.py", line 367, in _handle_entity_registry_updated
    await self._sync_helper(to_update, to_remove)
  File "/usr/src/homeassistant/homeassistant/components/cloud/alexa_config.py", line 311, in _sync_helper
    await self.async_get_access_token()
  File "/usr/src/homeassistant/homeassistant/components/cloud/alexa_config.py", line 173, in async_get_access_token
    raise alexa_errors.RequireRelink
homeassistant.components.alexa.errors.RequireRelink
2022-06-18 19:27:12 WARNING (MainThread) [hass_nabucasa.cloud_api] Fetched https://alexa-api.nabucasa.com/access_token (400)
2022-06-18 19:27:12 ERROR (MainThread) [homeassistant] Error doing job: Task exception was never retrieved
Traceback (most recent call last):
  File "/usr/src/homeassistant/homeassistant/components/cloud/alexa_config.py", line 367, in _handle_entity_registry_updated
    await self._sync_helper(to_update, to_remove)
  File "/usr/src/homeassistant/homeassistant/components/cloud/alexa_config.py", line 311, in _sync_helper
    await self.async_get_access_token()
  File "/usr/src/homeassistant/homeassistant/components/cloud/alexa_config.py", line 173, in async_get_access_token
    raise alexa_errors.RequireRelink
homeassistant.components.alexa.errors.RequireRelink
2022-06-18 19:27:12 WARNING (MainThread) [hass_nabucasa.cloud_api] Fetched https://alexa-api.nabucasa.com/access_token (400)
2022-06-18 19:27:12 ERROR (MainThread) [homeassistant] Error doing job: Task exception was never retrieved
Traceback (most recent call last):
  File "/usr/src/homeassistant/homeassistant/components/cloud/alexa_config.py", line 367, in _handle_entity_registry_updated
    await self._sync_helper(to_update, to_remove)
  File "/usr/src/homeassistant/homeassistant/components/cloud/alexa_config.py", line 311, in _sync_helper
    await self.async_get_access_token()
  File "/usr/src/homeassistant/homeassistant/components/cloud/alexa_config.py", line 173, in async_get_access_token
    raise alexa_errors.RequireRelink
homeassistant.components.alexa.errors.RequireRelink
2022-06-18 19:27:12 WARNING (MainThread) [hass_nabucasa.cloud_api] Fetched https://alexa-api.nabucasa.com/access_token (400)
2022-06-18 19:27:12 ERROR (MainThread) [homeassistant] Error doing job: Task exception was never retrieved
Traceback (most recent call last):
  File "/usr/src/homeassistant/homeassistant/components/cloud/alexa_config.py", line 367, in _handle_entity_registry_updated
    await self._sync_helper(to_update, to_remove)
  File "/usr/src/homeassistant/homeassistant/components/cloud/alexa_config.py", line 311, in _sync_helper
    await self.async_get_access_token()
  File "/usr/src/homeassistant/homeassistant/components/cloud/alexa_config.py", line 173, in async_get_access_token
    raise alexa_errors.RequireRelink
homeassistant.components.alexa.errors.RequireRelink
2022-06-18 19:27:12 WARNING (MainThread) [hass_nabucasa.cloud_api] Fetched https://alexa-api.nabucasa.com/access_token (400)
2022-06-18 19:27:12 ERROR (MainThread) [homeassistant] Error doing job: Task exception was never retrieved
Traceback (most recent call last):
  File "/usr/src/homeassistant/homeassistant/components/cloud/alexa_config.py", line 367, in _handle_entity_registry_updated
    await self._sync_helper(to_update, to_remove)
  File "/usr/src/homeassistant/homeassistant/components/cloud/alexa_config.py", line 311, in _sync_helper
    await self.async_get_access_token()
  File "/usr/src/homeassistant/homeassistant/components/cloud/alexa_config.py", line 173, in async_get_access_token
    raise alexa_errors.RequireRelink
homeassistant.components.alexa.errors.RequireRelink
2022-06-18 19:27:12 WARNING (MainThread) [hass_nabucasa.cloud_api] Fetched https://alexa-api.nabucasa.com/access_token (400)
2022-06-18 19:27:12 ERROR (MainThread) [homeassistant] Error doing job: Task exception was never retrieved
Traceback (most recent call last):
  File "/usr/src/homeassistant/homeassistant/components/cloud/alexa_config.py", line 367, in _handle_entity_registry_updated
    await self._sync_helper(to_update, to_remove)
  File "/usr/src/homeassistant/homeassistant/components/cloud/alexa_config.py", line 311, in _sync_helper
    await self.async_get_access_token()
  File "/usr/src/homeassistant/homeassistant/components/cloud/alexa_config.py", line 173, in async_get_access_token
    raise alexa_errors.RequireRelink
homeassistant.components.alexa.errors.RequireRelink
2022-06-18 19:27:12 WARNING (MainThread) [hass_nabucasa.cloud_api] Fetched https://alexa-api.nabucasa.com/access_token (400)
2022-06-18 19:27:12 ERROR (MainThread) [homeassistant] Error doing job: Task exception was never retrieved
Traceback (most recent call last):
  File "/usr/src/homeassistant/homeassistant/components/cloud/alexa_config.py", line 367, in _handle_entity_registry_updated
    await self._sync_helper(to_update, to_remove)
  File "/usr/src/homeassistant/homeassistant/components/cloud/alexa_config.py", line 311, in _sync_helper
    await self.async_get_access_token()
  File "/usr/src/homeassistant/homeassistant/components/cloud/alexa_config.py", line 173, in async_get_access_token
    raise alexa_errors.RequireRelink
homeassistant.components.alexa.errors.RequireRelink
2022-06-18 19:27:12 WARNING (MainThread) [hass_nabucasa.cloud_api] Fetched https://alexa-api.nabucasa.com/access_token (400)
2022-06-18 19:27:12 ERROR (MainThread) [homeassistant] Error doing job: Task exception was never retrieved
Traceback (most recent call last):
  File "/usr/src/homeassistant/homeassistant/components/cloud/alexa_config.py", line 367, in _handle_entity_registry_updated
    await self._sync_helper(to_update, to_remove)
  File "/usr/src/homeassistant/homeassistant/components/cloud/alexa_config.py", line 311, in _sync_helper
    await self.async_get_access_token()
  File "/usr/src/homeassistant/homeassistant/components/cloud/alexa_config.py", line 173, in async_get_access_token
    raise alexa_errors.RequireRelink
homeassistant.components.alexa.errors.RequireRelink
2022-06-18 19:27:12 WARNING (MainThread) [hass_nabucasa.cloud_api] Fetched https://alexa-api.nabucasa.com/access_token (400)
2022-06-18 19:27:12 ERROR (MainThread) [homeassistant] Error doing job: Task exception was never retrieved
Traceback (most recent call last):
  File "/usr/src/homeassistant/homeassistant/components/cloud/alexa_config.py", line 367, in _handle_entity_registry_updated
    await self._sync_helper(to_update, to_remove)
  File "/usr/src/homeassistant/homeassistant/components/cloud/alexa_config.py", line 311, in _sync_helper
    await self.async_get_access_token()
  File "/usr/src/homeassistant/homeassistant/components/cloud/alexa_config.py", line 173, in async_get_access_token
    raise alexa_errors.RequireRelink
homeassistant.components.alexa.errors.RequireRelink
2022-06-18 19:27:12 WARNING (MainThread) [hass_nabucasa.cloud_api] Fetched https://alexa-api.nabucasa.com/access_token (400)
2022-06-18 19:27:12 ERROR (MainThread) [homeassistant] Error doing job: Task exception was never retrieved
Traceback (most recent call last):
  File "/usr/src/homeassistant/homeassistant/components/cloud/alexa_config.py", line 367, in _handle_entity_registry_updated
    await self._sync_helper(to_update, to_remove)
  File "/usr/src/homeassistant/homeassistant/components/cloud/alexa_config.py", line 311, in _sync_helper
    await self.async_get_access_token()
  File "/usr/src/homeassistant/homeassistant/components/cloud/alexa_config.py", line 173, in async_get_access_token
    raise alexa_errors.RequireRelink
homeassistant.components.alexa.errors.RequireRelink
2022-06-18 19:27:12 WARNING (MainThread) [hass_nabucasa.cloud_api] Fetched https://alexa-api.nabucasa.com/access_token (400)
2022-06-18 19:27:12 ERROR (MainThread) [homeassistant] Error doing job: Task exception was never retrieved
Traceback (most recent call last):
  File "/usr/src/homeassistant/homeassistant/components/cloud/alexa_config.py", line 367, in _handle_entity_registry_updated
    await self._sync_helper(to_update, to_remove)
  File "/usr/src/homeassistant/homeassistant/components/cloud/alexa_config.py", line 311, in _sync_helper
    await self.async_get_access_token()
  File "/usr/src/homeassistant/homeassistant/components/cloud/alexa_config.py", line 173, in async_get_access_token
    raise alexa_errors.RequireRelink
homeassistant.components.alexa.errors.RequireRelink
2022-06-18 19:27:12 WARNING (MainThread) [hass_nabucasa.cloud_api] Fetched https://alexa-api.nabucasa.com/access_token (400)
2022-06-18 19:27:12 ERROR (MainThread) [homeassistant] Error doing job: Task exception was never retrieved
Traceback (most recent call last):
  File "/usr/src/homeassistant/homeassistant/components/cloud/alexa_config.py", line 367, in _handle_entity_registry_updated
    await self._sync_helper(to_update, to_remove)
  File "/usr/src/homeassistant/homeassistant/components/cloud/alexa_config.py", line 311, in _sync_helper
    await self.async_get_access_token()
  File "/usr/src/homeassistant/homeassistant/components/cloud/alexa_config.py", line 173, in async_get_access_token
    raise alexa_errors.RequireRelink
homeassistant.components.alexa.errors.RequireRelink
2022-06-18 19:27:12 WARNING (MainThread) [hass_nabucasa.cloud_api] Fetched https://alexa-api.nabucasa.com/access_token (400)
2022-06-18 19:27:12 ERROR (MainThread) [homeassistant] Error doing job: Task exception was never retrieved
Traceback (most recent call last):
  File "/usr/src/homeassistant/homeassistant/components/cloud/alexa_config.py", line 367, in _handle_entity_registry_updated
    await self._sync_helper(to_update, to_remove)
  File "/usr/src/homeassistant/homeassistant/components/cloud/alexa_config.py", line 311, in _sync_helper
    await self.async_get_access_token()
  File "/usr/src/homeassistant/homeassistant/components/cloud/alexa_config.py", line 173, in async_get_access_token
    raise alexa_errors.RequireRelink
homeassistant.components.alexa.errors.RequireRelink
2022-06-18 19:27:12 WARNING (MainThread) [hass_nabucasa.cloud_api] Fetched https://alexa-api.nabucasa.com/access_token (400)
2022-06-18 19:27:12 ERROR (MainThread) [homeassistant] Error doing job: Task exception was never retrieved
Traceback (most recent call last):
  File "/usr/src/homeassistant/homeassistant/components/cloud/alexa_config.py", line 367, in _handle_entity_registry_updated
    await self._sync_helper(to_update, to_remove)
  File "/usr/src/homeassistant/homeassistant/components/cloud/alexa_config.py", line 311, in _sync_helper
    await self.async_get_access_token()
  File "/usr/src/homeassistant/homeassistant/components/cloud/alexa_config.py", line 173, in async_get_access_token
    raise alexa_errors.RequireRelink
homeassistant.components.alexa.errors.RequireRelink
2022-06-18 19:27:12 WARNING (MainThread) [hass_nabucasa.cloud_api] Fetched https://alexa-api.nabucasa.com/access_token (400)
2022-06-18 19:27:12 ERROR (MainThread) [homeassistant] Error doing job: Task exception was never retrieved
Traceback (most recent call last):
  File "/usr/src/homeassistant/homeassistant/components/cloud/alexa_config.py", line 367, in _handle_entity_registry_updated
    await self._sync_helper(to_update, to_remove)
  File "/usr/src/homeassistant/homeassistant/components/cloud/alexa_config.py", line 311, in _sync_helper
    await self.async_get_access_token()
  File "/usr/src/homeassistant/homeassistant/components/cloud/alexa_config.py", line 173, in async_get_access_token
    raise alexa_errors.RequireRelink
homeassistant.components.alexa.errors.RequireRelink
2022-06-18 19:27:12 WARNING (MainThread) [hass_nabucasa.cloud_api] Fetched https://alexa-api.nabucasa.com/access_token (400)
2022-06-18 19:27:12 ERROR (MainThread) [homeassistant] Error doing job: Task exception was never retrieved
Traceback (most recent call last):
  File "/usr/src/homeassistant/homeassistant/components/cloud/alexa_config.py", line 367, in _handle_entity_registry_updated
    await self._sync_helper(to_update, to_remove)
  File "/usr/src/homeassistant/homeassistant/components/cloud/alexa_config.py", line 311, in _sync_helper
    await self.async_get_access_token()
  File "/usr/src/homeassistant/homeassistant/components/cloud/alexa_config.py", line 173, in async_get_access_token
    raise alexa_errors.RequireRelink
homeassistant.components.alexa.errors.RequireRelink
2022-06-18 19:27:45 WARNING (MainThread) [hass_nabucasa.cloud_api] Fetched https://alexa-api.nabucasa.com/access_token (400)
2022-06-18 19:27:45 ERROR (MainThread) [homeassistant] Error doing job: Task exception was never retrieved
Traceback (most recent call last):
  File "/usr/src/homeassistant/homeassistant/components/cloud/alexa_config.py", line 367, in _handle_entity_registry_updated
    await self._sync_helper(to_update, to_remove)
  File "/usr/src/homeassistant/homeassistant/components/cloud/alexa_config.py", line 311, in _sync_helper
    await self.async_get_access_token()
  File "/usr/src/homeassistant/homeassistant/components/cloud/alexa_config.py", line 173, in async_get_access_token
    raise alexa_errors.RequireRelink
homeassistant.components.alexa.errors.RequireRelink
2022-06-18 19:27:45 WARNING (MainThread) [hass_nabucasa.cloud_api] Fetched https://alexa-api.nabucasa.com/access_token (400)
2022-06-18 19:27:45 ERROR (MainThread) [homeassistant] Error doing job: Task exception was never retrieved
Traceback (most recent call last):
  File "/usr/src/homeassistant/homeassistant/components/cloud/alexa_config.py", line 367, in _handle_entity_registry_updated
    await self._sync_helper(to_update, to_remove)
  File "/usr/src/homeassistant/homeassistant/components/cloud/alexa_config.py", line 311, in _sync_helper
    await self.async_get_access_token()
  File "/usr/src/homeassistant/homeassistant/components/cloud/alexa_config.py", line 173, in async_get_access_token
    raise alexa_errors.RequireRelink
homeassistant.components.alexa.errors.RequireRelink
2022-06-18 19:27:45 WARNING (MainThread) [hass_nabucasa.cloud_api] Fetched https://alexa-api.nabucasa.com/access_token (400)
2022-06-18 19:27:45 ERROR (MainThread) [homeassistant] Error doing job: Task exception was never retrieved
Traceback (most recent call last):
  File "/usr/src/homeassistant/homeassistant/components/cloud/alexa_config.py", line 367, in _handle_entity_registry_updated
    await self._sync_helper(to_update, to_remove)
  File "/usr/src/homeassistant/homeassistant/components/cloud/alexa_config.py", line 311, in _sync_helper
    await self.async_get_access_token()
  File "/usr/src/homeassistant/homeassistant/components/cloud/alexa_config.py", line 173, in async_get_access_token
    raise alexa_errors.RequireRelink
homeassistant.components.alexa.errors.RequireRelink
2022-06-18 19:27:45 WARNING (MainThread) [hass_nabucasa.cloud_api] Fetched https://alexa-api.nabucasa.com/access_token (400)
2022-06-18 19:27:45 ERROR (MainThread) [homeassistant] Error doing job: Task exception was never retrieved
Traceback (most recent call last):
  File "/usr/src/homeassistant/homeassistant/components/cloud/alexa_config.py", line 367, in _handle_entity_registry_updated
    await self._sync_helper(to_update, to_remove)
  File "/usr/src/homeassistant/homeassistant/components/cloud/alexa_config.py", line 311, in _sync_helper
    await self.async_get_access_token()
  File "/usr/src/homeassistant/homeassistant/components/cloud/alexa_config.py", line 173, in async_get_access_token
    raise alexa_errors.RequireRelink
homeassistant.components.alexa.errors.RequireRelink
2022-06-18 19:27:45 WARNING (MainThread) [hass_nabucasa.cloud_api] Fetched https://alexa-api.nabucasa.com/access_token (400)
2022-06-18 19:27:45 ERROR (MainThread) [homeassistant] Error doing job: Task exception was never retrieved
Traceback (most recent call last):
  File "/usr/src/homeassistant/homeassistant/components/cloud/alexa_config.py", line 367, in _handle_entity_registry_updated
    await self._sync_helper(to_update, to_remove)
  File "/usr/src/homeassistant/homeassistant/components/cloud/alexa_config.py", line 311, in _sync_helper
    await self.async_get_access_token()
  File "/usr/src/homeassistant/homeassistant/components/cloud/alexa_config.py", line 173, in async_get_access_token
    raise alexa_errors.RequireRelink
homeassistant.components.alexa.errors.RequireRelink
2022-06-18 19:27:45 WARNING (MainThread) [hass_nabucasa.cloud_api] Fetched https://alexa-api.nabucasa.com/access_token (400)
2022-06-18 19:27:45 ERROR (MainThread) [homeassistant] Error doing job: Task exception was never retrieved
Traceback (most recent call last):
  File "/usr/src/homeassistant/homeassistant/components/cloud/alexa_config.py", line 367, in _handle_entity_registry_updated
    await self._sync_helper(to_update, to_remove)
  File "/usr/src/homeassistant/homeassistant/components/cloud/alexa_config.py", line 311, in _sync_helper
    await self.async_get_access_token()
  File "/usr/src/homeassistant/homeassistant/components/cloud/alexa_config.py", line 173, in async_get_access_token
    raise alexa_errors.RequireRelink
homeassistant.components.alexa.errors.RequireRelink
2022-06-18 19:27:45 WARNING (MainThread) [hass_nabucasa.cloud_api] Fetched https://alexa-api.nabucasa.com/access_token (400)
2022-06-18 19:27:45 ERROR (MainThread) [homeassistant] Error doing job: Task exception was never retrieved
Traceback (most recent call last):
  File "/usr/src/homeassistant/homeassistant/components/cloud/alexa_config.py", line 367, in _handle_entity_registry_updated
    await self._sync_helper(to_update, to_remove)
  File "/usr/src/homeassistant/homeassistant/components/cloud/alexa_config.py", line 311, in _sync_helper
    await self.async_get_access_token()
  File "/usr/src/homeassistant/homeassistant/components/cloud/alexa_config.py", line 173, in async_get_access_token
    raise alexa_errors.RequireRelink
homeassistant.components.alexa.errors.RequireRelink
2022-06-18 19:27:45 WARNING (MainThread) [hass_nabucasa.cloud_api] Fetched https://alexa-api.nabucasa.com/access_token (400)
2022-06-18 19:27:45 ERROR (MainThread) [homeassistant] Error doing job: Task exception was never retrieved
Traceback (most recent call last):
  File "/usr/src/homeassistant/homeassistant/components/cloud/alexa_config.py", line 367, in _handle_entity_registry_updated
    await self._sync_helper(to_update, to_remove)
  File "/usr/src/homeassistant/homeassistant/components/cloud/alexa_config.py", line 311, in _sync_helper
    await self.async_get_access_token()
  File "/usr/src/homeassistant/homeassistant/components/cloud/alexa_config.py", line 173, in async_get_access_token
    raise alexa_errors.RequireRelink
homeassistant.components.alexa.errors.RequireRelink
2022-06-18 19:27:45 WARNING (MainThread) [hass_nabucasa.cloud_api] Fetched https://alexa-api.nabucasa.com/access_token (400)
2022-06-18 19:27:45 ERROR (MainThread) [homeassistant] Error doing job: Task exception was never retrieved
Traceback (most recent call last):
  File "/usr/src/homeassistant/homeassistant/components/cloud/alexa_config.py", line 367, in _handle_entity_registry_updated
    await self._sync_helper(to_update, to_remove)
  File "/usr/src/homeassistant/homeassistant/components/cloud/alexa_config.py", line 311, in _sync_helper
    await self.async_get_access_token()
  File "/usr/src/homeassistant/homeassistant/components/cloud/alexa_config.py", line 173, in async_get_access_token
    raise alexa_errors.RequireRelink
homeassistant.components.alexa.errors.RequireRelink
2022-06-18 19:27:45 WARNING (MainThread) [hass_nabucasa.cloud_api] Fetched https://alexa-api.nabucasa.com/access_token (400)
2022-06-18 19:27:45 ERROR (MainThread) [homeassistant] Error doing job: Task exception was never retrieved
Traceback (most recent call last):
  File "/usr/src/homeassistant/homeassistant/components/cloud/alexa_config.py", line 367, in _handle_entity_registry_updated
    await self._sync_helper(to_update, to_remove)
  File "/usr/src/homeassistant/homeassistant/components/cloud/alexa_config.py", line 311, in _sync_helper
    await self.async_get_access_token()
  File "/usr/src/homeassistant/homeassistant/components/cloud/alexa_config.py", line 173, in async_get_access_token
    raise alexa_errors.RequireRelink
homeassistant.components.alexa.errors.RequireRelink
2022-06-18 19:27:45 WARNING (MainThread) [hass_nabucasa.cloud_api] Fetched https://alexa-api.nabucasa.com/access_token (400)
2022-06-18 19:27:45 ERROR (MainThread) [homeassistant] Error doing job: Task exception was never retrieved
Traceback (most recent call last):
  File "/usr/src/homeassistant/homeassistant/components/cloud/alexa_config.py", line 367, in _handle_entity_registry_updated
    await self._sync_helper(to_update, to_remove)
  File "/usr/src/homeassistant/homeassistant/components/cloud/alexa_config.py", line 311, in _sync_helper
    await self.async_get_access_token()
  File "/usr/src/homeassistant/homeassistant/components/cloud/alexa_config.py", line 173, in async_get_access_token
    raise alexa_errors.RequireRelink
homeassistant.components.alexa.errors.RequireRelink
2022-06-18 19:27:45 WARNING (MainThread) [hass_nabucasa.cloud_api] Fetched https://alexa-api.nabucasa.com/access_token (400)
2022-06-18 19:27:45 ERROR (MainThread) [homeassistant] Error doing job: Task exception was never retrieved
Traceback (most recent call last):
  File "/usr/src/homeassistant/homeassistant/components/cloud/alexa_config.py", line 367, in _handle_entity_registry_updated
    await self._sync_helper(to_update, to_remove)
  File "/usr/src/homeassistant/homeassistant/components/cloud/alexa_config.py", line 311, in _sync_helper
    await self.async_get_access_token()
  File "/usr/src/homeassistant/homeassistant/components/cloud/alexa_config.py", line 173, in async_get_access_token
    raise alexa_errors.RequireRelink
homeassistant.components.alexa.errors.RequireRelink
2022-06-18 19:27:45 WARNING (MainThread) [hass_nabucasa.cloud_api] Fetched https://alexa-api.nabucasa.com/access_token (400)
2022-06-18 19:27:45 ERROR (MainThread) [homeassistant] Error doing job: Task exception was never retrieved
Traceback (most recent call last):
  File "/usr/src/homeassistant/homeassistant/components/cloud/alexa_config.py", line 367, in _handle_entity_registry_updated
    await self._sync_helper(to_update, to_remove)
  File "/usr/src/homeassistant/homeassistant/components/cloud/alexa_config.py", line 311, in _sync_helper
    await self.async_get_access_token()
  File "/usr/src/homeassistant/homeassistant/components/cloud/alexa_config.py", line 173, in async_get_access_token
    raise alexa_errors.RequireRelink
homeassistant.components.alexa.errors.RequireRelink
2022-06-18 19:27:45 WARNING (MainThread) [hass_nabucasa.cloud_api] Fetched https://alexa-api.nabucasa.com/access_token (400)
2022-06-18 19:27:45 ERROR (MainThread) [homeassistant] Error doing job: Task exception was never retrieved
Traceback (most recent call last):
  File "/usr/src/homeassistant/homeassistant/components/cloud/alexa_config.py", line 367, in _handle_entity_registry_updated
    await self._sync_helper(to_update, to_remove)
  File "/usr/src/homeassistant/homeassistant/components/cloud/alexa_config.py", line 311, in _sync_helper
    await self.async_get_access_token()
  File "/usr/src/homeassistant/homeassistant/components/cloud/alexa_config.py", line 173, in async_get_access_token
    raise alexa_errors.RequireRelink
homeassistant.components.alexa.errors.RequireRelink
2022-06-18 19:27:45 WARNING (MainThread) [hass_nabucasa.cloud_api] Fetched https://alexa-api.nabucasa.com/access_token (400)
2022-06-18 19:27:45 ERROR (MainThread) [homeassistant] Error doing job: Task exception was never retrieved
Traceback (most recent call last):
  File "/usr/src/homeassistant/homeassistant/components/cloud/alexa_config.py", line 367, in _handle_entity_registry_updated
    await self._sync_helper(to_update, to_remove)
  File "/usr/src/homeassistant/homeassistant/components/cloud/alexa_config.py", line 311, in _sync_helper
    await self.async_get_access_token()
  File "/usr/src/homeassistant/homeassistant/components/cloud/alexa_config.py", line 173, in async_get_access_token
    raise alexa_errors.RequireRelink
homeassistant.components.alexa.errors.RequireRelink
2022-06-18 19:27:45 WARNING (MainThread) [hass_nabucasa.cloud_api] Fetched https://alexa-api.nabucasa.com/access_token (400)
2022-06-18 19:27:45 ERROR (MainThread) [homeassistant] Error doing job: Task exception was never retrieved
Traceback (most recent call last):
  File "/usr/src/homeassistant/homeassistant/components/cloud/alexa_config.py", line 367, in _handle_entity_registry_updated
    await self._sync_helper(to_update, to_remove)
  File "/usr/src/homeassistant/homeassistant/components/cloud/alexa_config.py", line 311, in _sync_helper
    await self.async_get_access_token()
  File "/usr/src/homeassistant/homeassistant/components/cloud/alexa_config.py", line 173, in async_get_access_token
    raise alexa_errors.RequireRelink
homeassistant.components.alexa.errors.RequireRelink
2022-06-18 19:27:45 WARNING (MainThread) [hass_nabucasa.cloud_api] Fetched https://alexa-api.nabucasa.com/access_token (400)
2022-06-18 19:27:45 ERROR (MainThread) [homeassistant] Error doing job: Task exception was never retrieved
Traceback (most recent call last):
  File "/usr/src/homeassistant/homeassistant/components/cloud/alexa_config.py", line 367, in _handle_entity_registry_updated
    await self._sync_helper(to_update, to_remove)
  File "/usr/src/homeassistant/homeassistant/components/cloud/alexa_config.py", line 311, in _sync_helper
    await self.async_get_access_token()
  File "/usr/src/homeassistant/homeassistant/components/cloud/alexa_config.py", line 173, in async_get_access_token
    raise alexa_errors.RequireRelink
homeassistant.components.alexa.errors.RequireRelink
2022-06-18 19:27:45 WARNING (MainThread) [hass_nabucasa.cloud_api] Fetched https://alexa-api.nabucasa.com/access_token (400)
2022-06-18 19:27:45 ERROR (MainThread) [homeassistant] Error doing job: Task exception was never retrieved
Traceback (most recent call last):
  File "/usr/src/homeassistant/homeassistant/components/cloud/alexa_config.py", line 367, in _handle_entity_registry_updated
    await self._sync_helper(to_update, to_remove)
  File "/usr/src/homeassistant/homeassistant/components/cloud/alexa_config.py", line 311, in _sync_helper
    await self.async_get_access_token()
  File "/usr/src/homeassistant/homeassistant/components/cloud/alexa_config.py", line 173, in async_get_access_token
    raise alexa_errors.RequireRelink
homeassistant.components.alexa.errors.RequireRelink
2022-06-18 19:27:45 WARNING (MainThread) [hass_nabucasa.cloud_api] Fetched https://alexa-api.nabucasa.com/access_token (400)
2022-06-18 19:27:45 ERROR (MainThread) [homeassistant] Error doing job: Task exception was never retrieved
Traceback (most recent call last):
  File "/usr/src/homeassistant/homeassistant/components/cloud/alexa_config.py", line 367, in _handle_entity_registry_updated
    await self._sync_helper(to_update, to_remove)
  File "/usr/src/homeassistant/homeassistant/components/cloud/alexa_config.py", line 311, in _sync_helper
    await self.async_get_access_token()
  File "/usr/src/homeassistant/homeassistant/components/cloud/alexa_config.py", line 173, in async_get_access_token
    raise alexa_errors.RequireRelink
homeassistant.components.alexa.errors.RequireRelink
2022-06-18 19:27:45 WARNING (MainThread) [hass_nabucasa.cloud_api] Fetched https://alexa-api.nabucasa.com/access_token (400)
2022-06-18 19:27:45 ERROR (MainThread) [homeassistant] Error doing job: Task exception was never retrieved
Traceback (most recent call last):
  File "/usr/src/homeassistant/homeassistant/components/cloud/alexa_config.py", line 367, in _handle_entity_registry_updated
    await self._sync_helper(to_update, to_remove)
  File "/usr/src/homeassistant/homeassistant/components/cloud/alexa_config.py", line 311, in _sync_helper
    await self.async_get_access_token()
  File "/usr/src/homeassistant/homeassistant/components/cloud/alexa_config.py", line 173, in async_get_access_token
    raise alexa_errors.RequireRelink
homeassistant.components.alexa.errors.RequireRelink
2022-06-18 19:27:45 WARNING (MainThread) [hass_nabucasa.cloud_api] Fetched https://alexa-api.nabucasa.com/access_token (400)
2022-06-18 19:27:45 ERROR (MainThread) [homeassistant] Error doing job: Task exception was never retrieved
Traceback (most recent call last):
  File "/usr/src/homeassistant/homeassistant/components/cloud/alexa_config.py", line 367, in _handle_entity_registry_updated
    await self._sync_helper(to_update, to_remove)
  File "/usr/src/homeassistant/homeassistant/components/cloud/alexa_config.py", line 311, in _sync_helper
    await self.async_get_access_token()
  File "/usr/src/homeassistant/homeassistant/components/cloud/alexa_config.py", line 173, in async_get_access_token
    raise alexa_errors.RequireRelink
homeassistant.components.alexa.errors.RequireRelink
2022-06-18 19:27:45 WARNING (MainThread) [hass_nabucasa.cloud_api] Fetched https://alexa-api.nabucasa.com/access_token (400)
2022-06-18 19:27:45 ERROR (MainThread) [homeassistant] Error doing job: Task exception was never retrieved
Traceback (most recent call last):
  File "/usr/src/homeassistant/homeassistant/components/cloud/alexa_config.py", line 367, in _handle_entity_registry_updated
    await self._sync_helper(to_update, to_remove)
  File "/usr/src/homeassistant/homeassistant/components/cloud/alexa_config.py", line 311, in _sync_helper
    await self.async_get_access_token()
  File "/usr/src/homeassistant/homeassistant/components/cloud/alexa_config.py", line 173, in async_get_access_token
    raise alexa_errors.RequireRelink
homeassistant.components.alexa.errors.RequireRelink
2022-06-18 19:27:45 WARNING (MainThread) [hass_nabucasa.cloud_api] Fetched https://alexa-api.nabucasa.com/access_token (400)
2022-06-18 19:27:45 ERROR (MainThread) [homeassistant] Error doing job: Task exception was never retrieved
Traceback (most recent call last):
  File "/usr/src/homeassistant/homeassistant/components/cloud/alexa_config.py", line 367, in _handle_entity_registry_updated
    await self._sync_helper(to_update, to_remove)
  File "/usr/src/homeassistant/homeassistant/components/cloud/alexa_config.py", line 311, in _sync_helper
    await self.async_get_access_token()
  File "/usr/src/homeassistant/homeassistant/components/cloud/alexa_config.py", line 173, in async_get_access_token
    raise alexa_errors.RequireRelink
homeassistant.components.alexa.errors.RequireRelink
2022-06-18 19:27:45 WARNING (MainThread) [hass_nabucasa.cloud_api] Fetched https://alexa-api.nabucasa.com/access_token (400)
2022-06-18 19:27:45 ERROR (MainThread) [homeassistant] Error doing job: Task exception was never retrieved
Traceback (most recent call last):
  File "/usr/src/homeassistant/homeassistant/components/cloud/alexa_config.py", line 367, in _handle_entity_registry_updated
    await self._sync_helper(to_update, to_remove)
  File "/usr/src/homeassistant/homeassistant/components/cloud/alexa_config.py", line 311, in _sync_helper
    await self.async_get_access_token()
  File "/usr/src/homeassistant/homeassistant/components/cloud/alexa_config.py", line 173, in async_get_access_token
    raise alexa_errors.RequireRelink
homeassistant.components.alexa.errors.RequireRelink
2022-06-18 19:27:45 WARNING (MainThread) [hass_nabucasa.cloud_api] Fetched https://alexa-api.nabucasa.com/access_token (400)
2022-06-18 19:27:45 ERROR (MainThread) [homeassistant] Error doing job: Task exception was never retrieved
Traceback (most recent call last):
  File "/usr/src/homeassistant/homeassistant/components/cloud/alexa_config.py", line 367, in _handle_entity_registry_updated
    await self._sync_helper(to_update, to_remove)
  File "/usr/src/homeassistant/homeassistant/components/cloud/alexa_config.py", line 311, in _sync_helper
    await self.async_get_access_token()
  File "/usr/src/homeassistant/homeassistant/components/cloud/alexa_config.py", line 173, in async_get_access_token
    raise alexa_errors.RequireRelink
homeassistant.components.alexa.errors.RequireRelink
2022-06-18 19:27:45 WARNING (MainThread) [hass_nabucasa.cloud_api] Fetched https://alexa-api.nabucasa.com/access_token (400)
2022-06-18 19:27:45 ERROR (MainThread) [homeassistant] Error doing job: Task exception was never retrieved
Traceback (most recent call last):
  File "/usr/src/homeassistant/homeassistant/components/cloud/alexa_config.py", line 367, in _handle_entity_registry_updated
    await self._sync_helper(to_update, to_remove)
  File "/usr/src/homeassistant/homeassistant/components/cloud/alexa_config.py", line 311, in _sync_helper
    await self.async_get_access_token()
  File "/usr/src/homeassistant/homeassistant/components/cloud/alexa_config.py", line 173, in async_get_access_token
    raise alexa_errors.RequireRelink
homeassistant.components.alexa.errors.RequireRelink
2022-06-18 19:27:45 WARNING (MainThread) [hass_nabucasa.cloud_api] Fetched https://alexa-api.nabucasa.com/access_token (400)
2022-06-18 19:27:45 ERROR (MainThread) [homeassistant] Error doing job: Task exception was never retrieved
Traceback (most recent call last):
  File "/usr/src/homeassistant/homeassistant/components/cloud/alexa_config.py", line 367, in _handle_entity_registry_updated
    await self._sync_helper(to_update, to_remove)
  File "/usr/src/homeassistant/homeassistant/components/cloud/alexa_config.py", line 311, in _sync_helper
    await self.async_get_access_token()
  File "/usr/src/homeassistant/homeassistant/components/cloud/alexa_config.py", line 173, in async_get_access_token
    raise alexa_errors.RequireRelink
homeassistant.components.alexa.errors.RequireRelink
2022-06-18 19:27:45 WARNING (MainThread) [hass_nabucasa.cloud_api] Fetched https://alexa-api.nabucasa.com/access_token (400)
2022-06-18 19:27:45 ERROR (MainThread) [homeassistant] Error doing job: Task exception was never retrieved
Traceback (most recent call last):
  File "/usr/src/homeassistant/homeassistant/components/cloud/alexa_config.py", line 367, in _handle_entity_registry_updated
    await self._sync_helper(to_update, to_remove)
  File "/usr/src/homeassistant/homeassistant/components/cloud/alexa_config.py", line 311, in _sync_helper
    await self.async_get_access_token()
  File "/usr/src/homeassistant/homeassistant/components/cloud/alexa_config.py", line 173, in async_get_access_token
    raise alexa_errors.RequireRelink
homeassistant.components.alexa.errors.RequireRelink
2022-06-18 19:27:45 WARNING (MainThread) [hass_nabucasa.cloud_api] Fetched https://alexa-api.nabucasa.com/access_token (400)
2022-06-18 19:27:45 ERROR (MainThread) [homeassistant] Error doing job: Task exception was never retrieved
Traceback (most recent call last):
  File "/usr/src/homeassistant/homeassistant/components/cloud/alexa_config.py", line 367, in _handle_entity_registry_updated
    await self._sync_helper(to_update, to_remove)
  File "/usr/src/homeassistant/homeassistant/components/cloud/alexa_config.py", line 311, in _sync_helper
    await self.async_get_access_token()
  File "/usr/src/homeassistant/homeassistant/components/cloud/alexa_config.py", line 173, in async_get_access_token
    raise alexa_errors.RequireRelink
homeassistant.components.alexa.errors.RequireRelink
2022-06-18 19:27:45 WARNING (MainThread) [hass_nabucasa.cloud_api] Fetched https://alexa-api.nabucasa.com/access_token (400)
2022-06-18 19:27:45 ERROR (MainThread) [homeassistant] Error doing job: Task exception was never retrieved
Traceback (most recent call last):
  File "/usr/src/homeassistant/homeassistant/components/cloud/alexa_config.py", line 367, in _handle_entity_registry_updated
    await self._sync_helper(to_update, to_remove)
  File "/usr/src/homeassistant/homeassistant/components/cloud/alexa_config.py", line 311, in _sync_helper
    await self.async_get_access_token()
  File "/usr/src/homeassistant/homeassistant/components/cloud/alexa_config.py", line 173, in async_get_access_token
    raise alexa_errors.RequireRelink
homeassistant.components.alexa.errors.RequireRelink
2022-06-18 19:27:46 WARNING (MainThread) [hass_nabucasa.cloud_api] Fetched https://alexa-api.nabucasa.com/access_token (400)
2022-06-18 19:27:46 ERROR (MainThread) [homeassistant] Error doing job: Task exception was never retrieved
Traceback (most recent call last):
  File "/usr/src/homeassistant/homeassistant/components/cloud/alexa_config.py", line 367, in _handle_entity_registry_updated
    await self._sync_helper(to_update, to_remove)
  File "/usr/src/homeassistant/homeassistant/components/cloud/alexa_config.py", line 311, in _sync_helper
    await self.async_get_access_token()
  File "/usr/src/homeassistant/homeassistant/components/cloud/alexa_config.py", line 173, in async_get_access_token
    raise alexa_errors.RequireRelink
homeassistant.components.alexa.errors.RequireRelink
2022-06-18 19:27:46 WARNING (MainThread) [hass_nabucasa.cloud_api] Fetched https://alexa-api.nabucasa.com/access_token (400)
2022-06-18 19:27:46 ERROR (MainThread) [homeassistant] Error doing job: Task exception was never retrieved
Traceback (most recent call last):
  File "/usr/src/homeassistant/homeassistant/components/cloud/alexa_config.py", line 367, in _handle_entity_registry_updated
    await self._sync_helper(to_update, to_remove)
  File "/usr/src/homeassistant/homeassistant/components/cloud/alexa_config.py", line 311, in _sync_helper
    await self.async_get_access_token()
  File "/usr/src/homeassistant/homeassistant/components/cloud/alexa_config.py", line 173, in async_get_access_token
    raise alexa_errors.RequireRelink
homeassistant.components.alexa.errors.RequireRelink
2022-06-19 02:38:05 ERROR (MainThread) [homeassistant] Error doing job: Task exception was never retrieved
Traceback (most recent call last):
  File "/usr/src/homeassistant/homeassistant/data_entry_flow.py", line 205, in async_init
    flow, result = await task
  File "/usr/src/homeassistant/homeassistant/data_entry_flow.py", line 232, in _async_init
    result = await self._async_handle_step(flow, flow.init_step, data, init_done)
  File "/usr/src/homeassistant/homeassistant/data_entry_flow.py", line 335, in _async_handle_step
    result: FlowResult = await getattr(flow, method)(user_input)
  File "/usr/src/homeassistant/homeassistant/components/ipp/config_flow.py", line 133, in async_step_zeroconf
    info = await validate_input(self.hass, self.discovery_info)
  File "/usr/src/homeassistant/homeassistant/components/ipp/config_flow.py", line 51, in validate_input
    printer = await ipp.printer()
  File "/usr/local/lib/python3.9/site-packages/pyipp/ipp.py", line 208, in printer
    response_data = await self.execute(
  File "/usr/local/lib/python3.9/site-packages/pyipp/ipp.py", line 177, in execute
    response = await self._request(data=message)
  File "/usr/local/lib/python3.9/site-packages/pyipp/ipp.py", line 146, in _request
    return await response.read()
  File "/usr/local/lib/python3.9/site-packages/aiohttp/client_reqrep.py", line 1036, in read
    self._body = await self.content.read()
  File "/usr/local/lib/python3.9/site-packages/aiohttp/streams.py", line 375, in read
    block = await self.readany()
  File "/usr/local/lib/python3.9/site-packages/aiohttp/streams.py", line 397, in readany
    await self._wait("readany")
  File "/usr/local/lib/python3.9/site-packages/aiohttp/streams.py", line 304, in _wait
    await waiter
  File "/usr/local/lib/python3.9/site-packages/aiohttp/helpers.py", line 721, in __exit__
    raise asyncio.TimeoutError from None
asyncio.exceptions.TimeoutError
2022-06-19 11:27:51 ERROR (MainThread) [frontend.js.latest.202206010] :0:0 Script error.
2022-06-19 11:28:48 ERROR (MainThread) [frontend.js.latest.202206010] :0:0 Script error.
2022-06-19 11:30:55 ERROR (MainThread) [frontend.js.latest.202206010] :0:0 Script error.
